Workbook

Sheet Data
A1: DateBag | B1: Site | C1: ID | D1: Week | E1: Station | F1: TreatmentNr | G1: DateSorting | H1: SorterID | I1: SpeciesTreatmentNr | J1: Species | K1: NbSeedStart | L1: SeedsCount | M1: DamagedSeedsCount | N1: SignsPredation | O1: Notes
A2: 45556 | B2: NEU | C2: MD | D2: 1 | E2: 1 | F2: 1 | G2: 45556 | H2: CW | I2: 2 | J2: Fagus sylvatica | K2: =IF(J2=Legend!$A$66,Legend!$B$66,(IF(J2=Legend!$A$67,Legend!$B$67,IF(J2=Legend!$A$68, Legend!$B$68, IF(J2=Legend!$A$69, Legend!$B$69, IF(J2=Legend!$A$70, Legend!$B$70, IF(J2=Legend!$A$71, Legend!$B$71, IF(J2=Legend!$A$72, Legend!$B$72, (IF(J2=Legend!$A$73, Legend!$B$73, IF(J2=Legend!$A$74, Legend!$B$74, ""))))))))))) -> 5 | L2: 5
A3: 45556 | B3: NEU | C3: MD | D3: 1 | E3: 1 | F3: 1 | G3: 45556 | H3: CW | I3: 2 | J3: Acer pseudoplatanus | K3: =IF(J3=Legend!$A$66,Legend!$B$66,(IF(J3=Legend!$A$67,Legend!$B$67,IF(J3=Legend!$A$68, Legend!$B$68, IF(J3=Legend!$A$69, Legend!$B$69, IF(J3=Legend!$A$70, Legend!$B$70, IF(J3=Legend!$A$71, Legend!$B$71, IF(J3=Legend!$A$72, Legend!$B$72, (IF(J3=Legend!$A$73, Legend!$B$73, IF(J3=Legend!$A$74, Legend!$B$74, ""))))))))))) -> 9 | L3: 9
A4: 45556 | B4: NEU | C4: MD | D4: 1 | E4: 1 | F4: 1 | G4: 45556 | H4: CW | I4: 2 | J4: Tillia cordata | K4: =IF(J4=Legend!$A$66,Legend!$B$66,(IF(J4=Legend!$A$67,Legend!$B$67,IF(J4=Legend!$A$68, Legend!$B$68, IF(J4=Legend!$A$69, Legend!$B$69, IF(J4=Legend!$A$70, Legend!$B$70, IF(J4=Legend!$A$71, Legend!$B$71, IF(J4=Legend!$A$72, Legend!$B$72, (IF(J4=Legend!$A$73, Legend!$B$73, IF(J4=Legend!$A$74, Legend!$B$74, ""))))))))))) -> 35 | L4: 36 | M4: 2 | N4: Crack | O4: 1 extra seed
A5: 45556 | B5: NEU | C5: MD | D5: 1 | E5: 1 | F5: 2 | G5: 45556 | H5: CW | I5: 2 | J5: Fagus sylvatica | K5: =IF(J5=Legend!$A$66,Legend!$B$66,(IF(J5=Legend!$A$67,Legend!$B$67,IF(J5=Legend!$A$68, Legend!$B$68, IF(J5=Legend!$A$69, Legend!$B$69, IF(J5=Legend!$A$70, Legend!$B$70, IF(J5=Legend!$A$71, Legend!$B$71, IF(J5=Legend!$A$72, Legend!$B$72, (IF(J5=Legend!$A$73, Legend!$B$73, IF(J5=Legend!$A$74, Legend!$B$74, ""))))))))))) -> 5 | L5: 5
A6: 45556 | B6: NEU | C6: MD | D6: 1 | E6: 1 | F6: 2 | G6: 45556 | H6: CW | I6: 2 | J6: Acer pseudoplatanus | K6: =IF(J6=Legend!$A$66,Legend!$B$66,(IF(J6=Legend!$A$67,Legend!$B$67,IF(J6=Legend!$A$68, Legend!$B$68, IF(J6=Legend!$A$69, Legend!$B$69, IF(J6=Legend!$A$70, Legend!$B$70, IF(J6=Legend!$A$71, Legend!$B$71, IF(J6=Legend!$A$72, Legend!$B$72, (IF(J6=Legend!$A$73, Legend!$B$73, IF(J6=Legend!$A$74, Legend!$B$74, ""))))))))))) -> 9 | L6: 9 | M6: 2 | N6: Hole and Crack
A7: 45556 | B7: NEU | C7: MD | D7: 1 | E7: 1 | F7: 2 | G7: 45556 | H7: CW | I7: 2 | J7: Tillia cordata | K7: =IF(J7=Legend!$A$66,Legend!$B$66,(IF(J7=Legend!$A$67,Legend!$B$67,IF(J7=Legend!$A$68, Legend!$B$68, IF(J7=Legend!$A$69, Legend!$B$69, IF(J7=Legend!$A$70, Legend!$B$70, IF(J7=Legend!$A$71, Legend!$B$71, IF(J7=Legend!$A$72, Legend!$B$72, (IF(J7=Legend!$A$73, Legend!$B$73, IF(J7=Legend!$A$74, Legend!$B$74, ""))))))))))) -> 35 | L7: 35 | M7: 2 | N7: Crack
A8: 45556 | B8: NEU | C8: MD | D8: 1 | E8: 3 | F8: 1 | G8: 45556 | H8: CW | I8: 2 | J8: Fagus sylvatica | K8: =IF(J8=Legend!$A$66,Legend!$B$66,(IF(J8=Legend!$A$67,Legend!$B$67,IF(J8=Legend!$A$68, Legend!$B$68, IF(J8=Legend!$A$69, Legend!$B$69, IF(J8=Legend!$A$70, Legend!$B$70, IF(J8=Legend!$A$71, Legend!$B$71, IF(J8=Legend!$A$72, Legend!$B$72, (IF(J8=Legend!$A$73, Legend!$B$73, IF(J8=Legend!$A$74, Legend!$B$74, ""))))))))))) -> 5 | L8: 5
A9: 45556 | B9: NEU | C9: MD | D9: 1 | E9: 3 | F9: 1 | G9: 45556 | H9: CW | I9: 2 | J9: Acer pseudoplatanus | K9: =IF(J9=Legend!$A$66,Legend!$B$66,(IF(J9=Legend!$A$67,Legend!$B$67,IF(J9=Legend!$A$68, Legend!$B$68, IF(J9=Legend!$A$69, Legend!$B$69, IF(J9=Legend!$A$70, Legend!$B$70, IF(J9=Legend!$A$71, Legend!$B$71, IF(J9=Legend!$A$72, Legend!$B$72, (IF(J9=Legend!$A$73, Legend!$B$73, IF(J9=Legend!$A$74, Legend!$B$74, ""))))))))))) -> 9 | L9: 9
A10: 45556 | B10: NEU | C10: MD | D10: 1 | E10: 3 | F10: 1 | G10: 45556 | H10: CW | I10: 2 | J10: Tillia cordata | K10: =IF(J10=Legend!$A$66,Legend!$B$66,(IF(J10=Legend!$A$67,Legend!$B$67,IF(J10=Legend!$A$68, Legend!$B$68, IF(J10=Legend!$A$69, Legend!$B$69, IF(J10=Legend!$A$70, Legend!$B$70, IF(J10=Legend!$A$71, Legend!$B$71, IF(J10=Legend!$A$72, Legend!$B$72, (IF(J10=Legend!$A$73, Legend!$B$73, IF(J10=Legend!$A$74, Legend!$B$74, ""))))))))))) -> 35 | L10: 35
A11: 45556 | B11: NEU | C11: MD | D11: 1 | E11: 3 | F11: 2 | G11: 45556 | H11: CW | I11: 2 | J11: Fagus sylvatica | K11: =IF(J11=Legend!$A$66,Legend!$B$66,(IF(J11=Legend!$A$67,Legend!$B$67,IF(J11=Legend!$A$68, Legend!$B$68, IF(J11=Legend!$A$69, Legend!$B$69, IF(J11=Legend!$A$70, Legend!$B$70, IF(J11=Legend!$A$71, Legend!$B$71, IF(J11=Legend!$A$72, Legend!$B$72, (IF(J11=Legend!$A$73, Legend!$B$73, IF(J11=Legend!$A$74, Legend!$B$74, ""))))))))))) -> 5 | L11: 5
A12: 45556 | B12: NEU | C12: MD | D12: 1 | E12: 3 | F12: 2 | G12: 45556 | H12: CW | I12: 2 | J12: Acer pseudoplatanus | K12: =IF(J12=Legend!$A$66,Legend!$B$66,(IF(J12=Legend!$A$67,Legend!$B$67,IF(J12=Legend!$A$68, Legend!$B$68, IF(J12=Legend!$A$69, Legend!$B$69, IF(J12=Legend!$A$70, Legend!$B$70, IF(J12=Legend!$A$71, Legend!$B$71, IF(J12=Legend!$A$72, Legend!$B$72, (IF(J12=Legend!$A$73, Legend!$B$73, IF(J12=Legend!$A$74, Legend!$B$74, ""))))))))))) -> 9 | L12: 9
A13: 45556 | B13: NEU | C13: MD | D13: 1 | E13: 3 | F13: 2 | G13: 45556 | H13: CW | I13: 2 | J13: Tillia cordata | K13: =IF(J13=Legend!$A$66,Legend!$B$66,(IF(J13=Legend!$A$67,Legend!$B$67,IF(J13=Legend!$A$68, Legend!$B$68, IF(J13=Legend!$A$69, Legend!$B$69, IF(J13=Legend!$A$70, Legend!$B$70, IF(J13=Legend!$A$71, Legend!$B$71, IF(J13=Legend!$A$72, Legend!$B$72, (IF(J13=Legend!$A$73, Legend!$B$73, IF(J13=Legend!$A$74, Legend!$B$74, ""))))))))))) -> 35 | L13: 35 | M13: 4 | N13: Crack
A14: 45556 | B14: NEU | C14: MD | D14: 1 | E14: 4 | F14: 1 | G14: 45556 | H14: CW | I14: 2 | J14: Fagus sylvatica | K14: =IF(J14=Legend!$A$66,Legend!$B$66,(IF(J14=Legend!$A$67,Legend!$B$67,IF(J14=Legend!$A$68, Legend!$B$68, IF(J14=Legend!$A$69, Legend!$B$69, IF(J14=Legend!$A$70, Legend!$B$70, IF(J14=Legend!$A$71, Legend!$B$71, IF(J14=Legend!$A$72, Legend!$B$72, (IF(J14=Legend!$A$73, Legend!$B$73, IF(J14=Legend!$A$74, Legend!$B$74, ""))))))))))) -> 5 | L14: 5
A15: 45556 | B15: NEU | C15: MD | D15: 1 | E15: 4 | F15: 1 | G15: 45556 | H15: CW | I15: 2 | J15: Acer pseudoplatanus | K15: =IF(J15=Legend!$A$66,Legend!$B$66,(IF(J15=Legend!$A$67,Legend!$B$67,IF(J15=Legend!$A$68, Legend!$B$68, IF(J15=Legend!$A$69, Legend!$B$69, IF(J15=Legend!$A$70, Legend!$B$70, IF(J15=Legend!$A$71, Legend!$B$71, IF(J15=Legend!$A$72, Legend!$B$72, (IF(J15=Legend!$A$73, Legend!$B$73, IF(J15=Legend!$A$74, Legend!$B$74, ""))))))))))) -> 9 | L15: 9 | M15: 1 | N15: Crack
A16: 45556 | B16: NEU | C16: MD | D16: 1 | E16: 4 | F16: 1 | G16: 45556 | H16: CW | I16: 2 | J16: Tillia cordata | K16: =IF(J16=Legend!$A$66,Legend!$B$66,(IF(J16=Legend!$A$67,Legend!$B$67,IF(J16=Legend!$A$68, Legend!$B$68, IF(J16=Legend!$A$69, Legend!$B$69, IF(J16=Legend!$A$70, Legend!$B$70, IF(J16=Legend!$A$71, Legend!$B$71, IF(J16=Legend!$A$72, Legend!$B$72, (IF(J16=Legend!$A$73, Legend!$B$73, IF(J16=Legend!$A$74, Legend!$B$74, ""))))))))))) -> 35 | L16: 35
A17: 45556 | B17: NEU | C17: MD | D17: 1 | E17: 4 | F17: 2 | G17: 45556 | H17: CW | I17: 2 | J17: Fagus sylvatica | K17: =IF(J17=Legend!$A$66,Legend!$B$66,(IF(J17=Legend!$A$67,Legend!$B$67,IF(J17=Legend!$A$68, Legend!$B$68, IF(J17=Legend!$A$69, Legend!$B$69, IF(J17=Legend!$A$70, Legend!$B$70, IF(J17=Legend!$A$71, Legend!$B$71, IF(J17=Legend!$A$72, Legend!$B$72, (IF(J17=Legend!$A$73, Legend!$B$73, IF(J17=Legend!$A$74, Legend!$B$74, ""))))))))))) -> 5 | L17: 5
A18: 45556 | B18: NEU | C18: MD | D18: 1 | E18: 4 | F18: 2 | G18: 45556 | H18: CW | I18: 2 | J18: Acer pseudoplatanus | K18: =IF(J18=Legend!$A$66,Legend!$B$66,(IF(J18=Legend!$A$67,Legend!$B$67,IF(J18=Legend!$A$68, Legend!$B$68, IF(J18=Legend!$A$69, Legend!$B$69, IF(J18=Legend!$A$70, Legend!$B$70, IF(J18=Legend!$A$71, Legend!$B$71, IF(J18=Legend!$A$72, Legend!$B$72, (IF(J18=Legend!$A$73, Legend!$B$73, IF(J18=Legend!$A$74, Legend!$B$74, ""))))))))))) -> 9 | L18: 9
A19: 45556 | B19: NEU | C19: MD | D19: 1 | E19: 4 | F19: 2 | G19: 45556 | H19: CW | I19: 2 | J19: Tillia cordata | K19: =IF(J19=Legend!$A$66,Legend!$B$66,(IF(J19=Legend!$A$67,Legend!$B$67,IF(J19=Legend!$A$68, Legend!$B$68, IF(J19=Legend!$A$69, Legend!$B$69, IF(J19=Legend!$A$70, Legend!$B$70, IF(J19=Legend!$A$71, Legend!$B$71, IF(J19=Legend!$A$72, Legend!$B$72, (IF(J19=Legend!$A$73, Legend!$B$73, IF(J19=Legend!$A$74, Legend!$B$74, ""))))))))))) -> 35 | L19: 35 | M19: 2 | N19: Crack
A20: 45556 | B20: NEU | C20: MD | D20: 1 | E20: 5 | F20: 1 | G20: 45556 | H20: CW | I20: 2 | J20: Fagus sylvatica | K20: =IF(J20=Legend!$A$66,Legend!$B$66,(IF(J20=Legend!$A$67,Legend!$B$67,IF(J20=Legend!$A$68, Legend!$B$68, IF(J20=Legend!$A$69, Legend!$B$69, IF(J20=Legend!$A$70, Legend!$B$70, IF(J20=Legend!$A$71, Legend!$B$71, IF(J20=Legend!$A$72, Legend!$B$72, (IF(J20=Legend!$A$73, Legend!$B$73, IF(J20=Legend!$A$74, Legend!$B$74, ""))))))))))) -> 5 | L20: 5
A21: 45556 | B21: NEU | C21: MD | D21: 1 | E21: 5 | F21: 1 | G21: 45556 | H21: CW | I21: 2 | J21: Acer pseudoplatanus | K21: =IF(J21=Legend!$A$66,Legend!$B$66,(IF(J21=Legend!$A$67,Legend!$B$67,IF(J21=Legend!$A$68, Legend!$B$68, IF(J21=Legend!$A$69, Legend!$B$69, IF(J21=Legend!$A$70, Legend!$B$70, IF(J21=Legend!$A$71, Legend!$B$71, IF(J21=Legend!$A$72, Legend!$B$72, (IF(J21=Legend!$A$73, Legend!$B$73, IF(J21=Legend!$A$74, Legend!$B$74, ""))))))))))) -> 9 | L21: 9
A22: 45556 | B22: NEU | C22: MD | D22: 1 | E22: 5 | F22: 1 | G22: 45556 | H22: CW | I22: 2 | J22: Tillia cordata | K22: =IF(J22=Legend!$A$66,Legend!$B$66,(IF(J22=Legend!$A$67,Legend!$B$67,IF(J22=Legend!$A$68, Legend!$B$68, IF(J22=Legend!$A$69, Legend!$B$69, IF(J22=Legend!$A$70, Legend!$B$70, IF(J22=Legend!$A$71, Legend!$B$71, IF(J22=Legend!$A$72, Legend!$B$72, (IF(J22=Legend!$A$73, Legend!$B$73, IF(J22=Legend!$A$74, Legend!$B$74, ""))))))))))) -> 35 | L22: 35 | M22: 1 | N22: Crack
A23: 45556 | B23: NEU | C23: MD | D23: 1 | E23: 5 | F23: 2 | G23: 45556 | H23: CW | I23: 2 | J23: Fagus sylvatica | K23: =IF(J23=Legend!$A$66,Legend!$B$66,(IF(J23=Legend!$A$67,Legend!$B$67,IF(J23=Legend!$A$68, Legend!$B$68, IF(J23=Legend!$A$69, Legend!$B$69, IF(J23=Legend!$A$70, Legend!$B$70, IF(J23=Legend!$A$71, Legend!$B$71, IF(J23=Legend!$A$72, Legend!$B$72, (IF(J23=Legend!$A$73, Legend!$B$73, IF(J23=Legend!$A$74, Legend!$B$74, ""))))))))))) -> 5 | L23: 5
A24: 45556 | B24: NEU | C24: MD | D24: 1 | E24: 5 | F24: 2 | G24: 45556 | H24: CW | I24: 2 | J24: Acer pseudoplatanus | K24: =IF(J24=Legend!$A$66,Legend!$B$66,(IF(J24=Legend!$A$67,Legend!$B$67,IF(J24=Legend!$A$68, Legend!$B$68, IF(J24=Legend!$A$69, Legend!$B$69, IF(J24=Legend!$A$70, Legend!$B$70, IF(J24=Legend!$A$71, Legend!$B$71, IF(J24=Legend!$A$72, Legend!$B$72, (IF(J24=Legend!$A$73, Legend!$B$73, IF(J24=Legend!$A$74, Legend!$B$74, ""))))))))))) -> 9 | L24: 10 | M24: 1 | N24: Crack | O24: 1 extra seed
A25: 45556 | B25: NEU | C25: MD | D25: 1 | E25: 5 | F25: 2 | G25: 45556 | H25: CW | I25: 2 | J25: Tillia cordata | K25: =IF(J25=Legend!$A$66,Legend!$B$66,(IF(J25=Legend!$A$67,Legend!$B$67,IF(J25=Legend!$A$68, Legend!$B$68, IF(J25=Legend!$A$69, Legend!$B$69, IF(J25=Legend!$A$70, Legend!$B$70, IF(J25=Legend!$A$71, Legend!$B$71, IF(J25=Legend!$A$72, Legend!$B$72, (IF(J25=Legend!$A$73, Legend!$B$73, IF(J25=Legend!$A$74, Legend!$B$74, ""))))))))))) -> 35 | L25: 35
A26: 45561 | B26: CEL | C26: OL | D26: 2 | E26: 1 | F26: 1 | G26: 45573 | H26: CW | I26: 4 | J26: Pinus cembra | K26: =IF(J26=Legend!$A$66,Legend!$B$66,(IF(J26=Legend!$A$67,Legend!$B$67,IF(J26=Legend!$A$68, Legend!$B$68, IF(J26=Legend!$A$69, Legend!$B$69, IF(J26=Legend!$A$70, Legend!$B$70, IF(J26=Legend!$A$71, Legend!$B$71, IF(J26=Legend!$A$72, Legend!$B$72, (IF(J26=Legend!$A$73, Legend!$B$73, IF(J26=Legend!$A$74, Legend!$B$74, ""))))))))))) -> 3 | L26: 3 | O26: 52 ants, 12 other insects
A27: 45561 | B27: CEL | C27: OL | D27: 2 | E27: 1 | F27: 1 | G27: 45573 | H27: CW | I27: 4 | J27: Larix decidua | K27: =IF(J27=Legend!$A$66,Legend!$B$66,(IF(J27=Legend!$A$67,Legend!$B$67,IF(J27=Legend!$A$68, Legend!$B$68, IF(J27=Legend!$A$69, Legend!$B$69, IF(J27=Legend!$A$70, Legend!$B$70, IF(J27=Legend!$A$71, Legend!$B$71, IF(J27=Legend!$A$72, Legend!$B$72, (IF(J27=Legend!$A$73, Legend!$B$73, IF(J27=Legend!$A$74, Legend!$B$74, ""))))))))))) -> 120 | L27: 120 | M27: 4 | N27: Hole and Crack
A28: 45561 | B28: CEL | C28: OL | D28: 2 | E28: 1 | F28: 2 | G28: 45573 | H28: CW | I28: 4 | J28: Pinus cembra | K28: =IF(J28=Legend!$A$66,Legend!$B$66,(IF(J28=Legend!$A$67,Legend!$B$67,IF(J28=Legend!$A$68, Legend!$B$68, IF(J28=Legend!$A$69, Legend!$B$69, IF(J28=Legend!$A$70, Legend!$B$70, IF(J28=Legend!$A$71, Legend!$B$71, IF(J28=Legend!$A$72, Legend!$B$72, (IF(J28=Legend!$A$73, Legend!$B$73, IF(J28=Legend!$A$74, Legend!$B$74, ""))))))))))) -> 3 | L28: 3 | O28: 1 ant, 7 other insects
A29: 45561 | B29: CEL | C29: OL | D29: 2 | E29: 1 | F29: 2 | G29: 45573 | H29: CW | I29: 4 | J29: Larix decidua | K29: =IF(J29=Legend!$A$66,Legend!$B$66,(IF(J29=Legend!$A$67,Legend!$B$67,IF(J29=Legend!$A$68, Legend!$B$68, IF(J29=Legend!$A$69, Legend!$B$69, IF(J29=Legend!$A$70, Legend!$B$70, IF(J29=Legend!$A$71, Legend!$B$71, IF(J29=Legend!$A$72, Legend!$B$72, (IF(J29=Legend!$A$73, Legend!$B$73, IF(J29=Legend!$A$74, Legend!$B$74, ""))))))))))) -> 120 | L29: 120
A30: 45561 | B30: CEL | C30: OL | D30: 2 | E30: 2 | F30: 1 | G30: 45573 | H30: CW | I30: 4 | J30: Pinus cembra | K30: =IF(J30=Legend!$A$66,Legend!$B$66,(IF(J30=Legend!$A$67,Legend!$B$67,IF(J30=Legend!$A$68, Legend!$B$68, IF(J30=Legend!$A$69, Legend!$B$69, IF(J30=Legend!$A$70, Legend!$B$70, IF(J30=Legend!$A$71, Legend!$B$71, IF(J30=Legend!$A$72, Legend!$B$72, (IF(J30=Legend!$A$73, Legend!$B$73, IF(J30=Legend!$A$74, Legend!$B$74, ""))))))))))) -> 3 | L30: 3
A31: 45561 | B31: CEL | C31: OL | D31: 2 | E31: 2 | F31: 1 | G31: 45573 | H31: CW | I31: 4 | J31: Larix decidua | K31: =IF(J31=Legend!$A$66,Legend!$B$66,(IF(J31=Legend!$A$67,Legend!$B$67,IF(J31=Legend!$A$68, Legend!$B$68, IF(J31=Legend!$A$69, Legend!$B$69, IF(J31=Legend!$A$70, Legend!$B$70, IF(J31=Legend!$A$71, Legend!$B$71, IF(J31=Legend!$A$72, Legend!$B$72, (IF(J31=Legend!$A$73, Legend!$B$73, IF(J31=Legend!$A$74, Legend!$B$74, ""))))))))))) -> 120 | L31: 120 | M31: 4 | N31: Hole
A32: 45561 | B32: CEL | C32: OL | D32: 2 | E32: 2 | F32: 2 | G32: 45573 | H32: CW | I32: 4 | J32: Pinus cembra | K32: =IF(J32=Legend!$A$66,Legend!$B$66,(IF(J32=Legend!$A$67,Legend!$B$67,IF(J32=Legend!$A$68, Legend!$B$68, IF(J32=Legend!$A$69, Legend!$B$69, IF(J32=Legend!$A$70, Legend!$B$70, IF(J32=Legend!$A$71, Legend!$B$71, IF(J32=Legend!$A$72, Legend!$B$72, (IF(J32=Legend!$A$73, Legend!$B$73, IF(J32=Legend!$A$74, Legend!$B$74, ""))))))))))) -> 3 | L32: 3
A33: 45561 | B33: CEL | C33: OL | D33: 2 | E33: 2 | F33: 2 | G33: 45573 | H33: CW | I33: 4 | J33: Larix decidua | K33: =IF(J33=Legend!$A$66,Legend!$B$66,(IF(J33=Legend!$A$67,Legend!$B$67,IF(J33=Legend!$A$68, Legend!$B$68, IF(J33=Legend!$A$69, Legend!$B$69, IF(J33=Legend!$A$70, Legend!$B$70, IF(J33=Legend!$A$71, Legend!$B$71, IF(J33=Legend!$A$72, Legend!$B$72, (IF(J33=Legend!$A$73, Legend!$B$73, IF(J33=Legend!$A$74, Legend!$B$74, ""))))))))))) -> 120 | L33: 120 | M33: 2 | N33: Hole and Crack
A34: 45561 | B34: CEL | C34: OL | D34: 2 | E34: 5 | F34: 1 | G34: 45573 | H34: CW | I34: 4 | J34: Pinus cembra | K34: =IF(J34=Legend!$A$66,Legend!$B$66,(IF(J34=Legend!$A$67,Legend!$B$67,IF(J34=Legend!$A$68, Legend!$B$68, IF(J34=Legend!$A$69, Legend!$B$69, IF(J34=Legend!$A$70, Legend!$B$70, IF(J34=Legend!$A$71, Legend!$B$71, IF(J34=Legend!$A$72, Legend!$B$72, (IF(J34=Legend!$A$73, Legend!$B$73, IF(J34=Legend!$A$74, Legend!$B$74, ""))))))))))) -> 3 | L34: 3 | O34: 4 ants, 15 other insects
A35: 45561 | B35: CEL | C35: OL | D35: 2 | E35: 5 | F35: 1 | G35: 45573 | H35: CW | I35: 4 | J35: Larix decidua | K35: =IF(J35=Legend!$A$66,Legend!$B$66,(IF(J35=Legend!$A$67,Legend!$B$67,IF(J35=Legend!$A$68, Legend!$B$68, IF(J35=Legend!$A$69, Legend!$B$69, IF(J35=Legend!$A$70, Legend!$B$70, IF(J35=Legend!$A$71, Legend!$B$71, IF(J35=Legend!$A$72, Legend!$B$72, (IF(J35=Legend!$A$73, Legend!$B$73, IF(J35=Legend!$A$74, Legend!$B$74, ""))))))))))) -> 120 | L35: 120 | M35: 4 | N35: Hole and Crack
A36: 45561 | B36: CEL | C36: OL | D36: 2 | E36: 5 | F36: 2 | G36: 45573 | H36: CW | I36: 4 | J36: Pinus cembra | K36: =IF(J36=Legend!$A$66,Legend!$B$66,(IF(J36=Legend!$A$67,Legend!$B$67,IF(J36=Legend!$A$68, Legend!$B$68, IF(J36=Legend!$A$69, Legend!$B$69, IF(J36=Legend!$A$70, Legend!$B$70, IF(J36=Legend!$A$71, Legend!$B$71, IF(J36=Legend!$A$72, Legend!$B$72, (IF(J36=Legend!$A$73, Legend!$B$73, IF(J36=Legend!$A$74, Legend!$B$74, ""))))))))))) -> 3 | L36: 3 | O36: 7 insects
A37: 45561 | B37: CEL | C37: OL | D37: 2 | E37: 5 | F37: 2 | G37: 45573 | H37: CW | I37: 4 | J37: Larix decidua | K37: =IF(J37=Legend!$A$66,Legend!$B$66,(IF(J37=Legend!$A$67,Legend!$B$67,IF(J37=Legend!$A$68, Legend!$B$68, IF(J37=Legend!$A$69, Legend!$B$69, IF(J37=Legend!$A$70, Legend!$B$70, IF(J37=Legend!$A$71, Legend!$B$71, IF(J37=Legend!$A$72, Legend!$B$72, (IF(J37=Legend!$A$73, Legend!$B$73, IF(J37=Legend!$A$74, Legend!$B$74, ""))))))))))) -> 120 | L37: 119 | M37: 4 | N37: Hole
A38: 45561 | B38: CEL | C38: OL | D38: 2 | E38: 6 | F38: 1 | G38: 45573 | H38: CW | I38: 4 | J38: Pinus cembra | K38: =IF(J38=Legend!$A$66,Legend!$B$66,(IF(J38=Legend!$A$67,Legend!$B$67,IF(J38=Legend!$A$68, Legend!$B$68, IF(J38=Legend!$A$69, Legend!$B$69, IF(J38=Legend!$A$70, Legend!$B$70, IF(J38=Legend!$A$71, Legend!$B$71, IF(J38=Legend!$A$72, Legend!$B$72, (IF(J38=Legend!$A$73, Legend!$B$73, IF(J38=Legend!$A$74, Legend!$B$74, ""))))))))))) -> 3 | L38: 3 | O38: 7 ants, 3 other insects
A39: 45561 | B39: CEL | C39: OL | D39: 2 | E39: 6 | F39: 1 | G39: 45573 | H39: CW | I39: 4 | J39: Larix decidua | K39: =IF(J39=Legend!$A$66,Legend!$B$66,(IF(J39=Legend!$A$67,Legend!$B$67,IF(J39=Legend!$A$68, Legend!$B$68, IF(J39=Legend!$A$69, Legend!$B$69, IF(J39=Legend!$A$70, Legend!$B$70, IF(J39=Legend!$A$71, Legend!$B$71, IF(J39=Legend!$A$72, Legend!$B$72, (IF(J39=Legend!$A$73, Legend!$B$73, IF(J39=Legend!$A$74, Legend!$B$74, ""))))))))))) -> 120 | L39: 120
A40: 45561 | B40: CEL | C40: OL | D40: 2 | E40: 6 | F40: 2 | G40: 45573 | H40: CW | I40: 4 | J40: Pinus cembra | K40: =IF(J40=Legend!$A$66,Legend!$B$66,(IF(J40=Legend!$A$67,Legend!$B$67,IF(J40=Legend!$A$68, Legend!$B$68, IF(J40=Legend!$A$69, Legend!$B$69, IF(J40=Legend!$A$70, Legend!$B$70, IF(J40=Legend!$A$71, Legend!$B$71, IF(J40=Legend!$A$72, Legend!$B$72, (IF(J40=Legend!$A$73, Legend!$B$73, IF(J40=Legend!$A$74, Legend!$B$74, ""))))))))))) -> 3 | L40: 3
...

Sheet Legend
A1: SEED SORTING DATASHEET INSTRUCTIONS
A3: How to save the data
A4: Access the polybox, in the 'Shared_SPP_CH' folder you can find the 'SeedSortingTemplate.xlsx' file.
A5: Download the file.
A6: Rename the file like this: "SeedSorting_Autumn24_<DDMMYYYY>_<YourInitials>.xlsx
A7: Upload the file in the polybox into this folder: Shared_SPP_CH>SeedSorting>SeedSortingData
A9: DateBag | B9: Date in the format dd/mm/yyyy
A11: Site
A12: BEA | B12: Beatenberg
A13: BET | B13: Bettlachstock
A14: CEL | B14: Celerina
A15: NAT | B15: Nationalpark
A16: NEU | B16: Neunkirch
A17: SCH | B17: Schänis
A18: VOR | B18: Vordemwald
A19: WAL | B19: Waldlabor
A21: ID | B21: Initials of the people collecting the seeds (check the paper bag)
A22: MD
A23: SG
A24: EP
A25: OL
A26: JN
A27: LW
A28: MD&SG
A29: MD&EP
A30: EP&SG | B30: if you find other initials add them with the simbol & in between
A32: Week
A33: 1
A34: 2
A35: 3
A37: Station | B37: number between 1 and 10
A38: 1
A39: 2
A40: 3
A41: 4
A42: 5
A43: 6
A44: 7
A45: 8
A46: 9
...
